Workbook
Name Analyst_Revenue_Growth: 'Input & Dashboard'!$B$4
Name Current_Price: 'Input & Dashboard'!$F$12
Name Elevated_globally: 'Input & Dashboard'!$B$17
Name EPS: 'Input & Dashboard'!$B$19
Name F_EPS: 'Input & Dashboard'!$D$9
Name Gross_Margin: 'Input & Dashboard'!$B$13
Name Gross_prcnt: 'Input & Dashboard'!$D$5
Name Inflation_rate_reg: Regression!$Q$42
Name Inflation_Target: 'Input & Dashboard'!$B$7
Name Intercept: Regression!$Q$41
Name Management_Revenue_Growth: 'Input & Dashboard'!$B$12
Name Net_prcnt: 'Input & Dashboard'!$D$6
Name NI_Q4: 'Updated Sheet'!$F$25
Name Nike_Digital_Sales: 'Input & Dashboard'!$B$15
Name Nike_Direct_Sales: 'Input & Dashboard'!$B$14
Name PE_Ratio_Competitors: Valuation!$D$16
Name Price_Sales_Ratio_Competitors: Valuation!$C$7:$C$14
Name PS_Ratio_Competitors: Valuation!$C$16
Name Q3_Revenue: 'Updated Sheet'!$C$24
Name Q4_COS: 'Updated Sheet'!$D$25
Name Q4_EPS_2024: 'Updated Sheet'!$O$25
Name Q4_Revenue: 'Updated Sheet'!$C$25
Name ROA: 'Input & Dashboard'!$D$7
Name ROE: 'Input & Dashboard'!$D$8
Name SG_A_Expenses: 'Input & Dashboard'!$B$18
Name Shares_Oustanding: 'Input & Dashboard'!$B$8
Name Target_Price: 'Input & Dashboard'!$J$5
Name TRGT_PE: Valuation!$D$18
Name TRGT_PRICE: 'Input & Dashboard'!$J$5
Name Trgt_PS: Valuation!$C$18
Name Wholesale_Sales: 'Input & Dashboard'!$B$16

Sheet Input & Dashboard
N3: Decision Input
A4: Analyst Revenue Growth | B4: 0.2 | D4: Discriptive Stats (Financial Ratios) | N4: Given Inputs
D5: Gross % | E5: Average | F5: =_xlfn.XLOOKUP(Gross_prcnt,'Updated Sheet'!$A$1:$O$1,'Updated Sheet'!$A$25:$O$25) -> 0.44419884 | I5: Target Price | J5: =SUMPRODUCT(K13:K14,J13:J14) -> 100.70059 | N5: Model Output
D6: Net % | E6: Average | F6: =_xlfn.XLOOKUP(Net_prcnt,'Updated Sheet'!$A$1:$O$1,'Updated Sheet'!$A$25:$O$25) -> 0.096450286 | I6: Revenue Growth Rate | J6: =Inflation_Target*Inflation_rate_reg+Intercept -> 0.076059392
A7: Inflation Target | B7: 0.05 | D7: ROA | E7: Median | F7: =_xlfn.XLOOKUP(ROA,'Updated Sheet'!$A$1:$O$1,'Updated Sheet'!$A$25:$O$25) -> 0.034534649 | I7: EPS | J7: =Q4_EPS_2024 -> 0.89459222
A8: Shares Oustanding | B8: 1499358944 | D8: ROE | E8: Median | F8: =_xlfn.XLOOKUP(ROE,'Updated Sheet'!$A$1:$O$1,'Updated Sheet'!$A$25:$O$25) -> 0.092274968
D9: EPS | E9: Median | F9: =_xlfn.XLOOKUP(F_EPS,'Updated Sheet'!$A$1:$O$1,'Updated Sheet'!$A$25:$O$25) -> 0.89459222 | I9: Margin of Error | J9: 0.2 | K9: =TRGT_PRICE-Current_Price -> 23.450593
I10: Buy/Sell | J10: =IF((Target_Price*(1-J9))>Current_Price,"Buy","Sell") -> Buy
A11: Management Assumptions | D11: Stock
A12: Management Revenue Growth | B12: 0.1 | D12: Current Price | F12: 77.25 | I12: Valuation Methods | J12: Weights
A13: Gross Margin | B13: 0.454 | I13: Price/Sales | J13: 0.5 | K13: =Trgt_PS -> 107.33034
A14: Nike Direct Sales | B14: -0.12 | I14: P/E | J14: =1-J13 -> 0.5 | K14: =TRGT_PE -> 94.070845
A15: Nike Digital Sales | B15: 0.2
A16: Wholesale Sales | B16: -0.07
A17: Inventory Levels | B17: Elevated globally
A18: SG&A Expenses | B18: 0.02
A19: EPS | B19: 0.7

Sheet Valuation
B6: Competition | C6: Price/Sales | D6: P/E | E6: EPS | F6: Market CAP (in billions) | H6: Metric | I6: Q1 2025 Results | J6: Management Expectation/Focus
B7: Adidas | C7: 1.93 | D7: 38.4 | E7: -0.23 | F7: 45.82 | H7: Revenue | I7: Down 10% | J7: Continued softness expected; focus on innovation-driven growth.
B8: Anta | C8: 3.55 | D8: 16.11 | E8: 0.45 | F8: 27.58 | H8: Gross Margin | I8: 45.4% (+120 basis points YoY) | J8: Expected to decline in Q2 due to promotional activities.
B9: Asics | C9: 3.4 | D9: 38.29 | E9: 0 | F9: 19.9 | H9: Nike Direct Sales | I9: Down 12% | J9: Aim to rebalance inventory and improve full-price realization.
B10: Deckers | C10: 6.79 | D10: 36.84 | E10: 1.59 | F10: 31.75 | H10: Nike Digital Sales | I10: Down 20% | J10: Improve performance through channel optimization.
B11: Li Ning | C11: 1.2 | D11: 14.66 | E11: 0.61 | F11: 5.59 | H11: Wholesale Sales | I11: Down 7% | J11: Partner support increasing; expected to stabilize.
B12: Lululemon Athletica | C12: 4.814 | D12: 27.3 | E12: 12.2 | F12: 46.78 | H12: Inventory Levels | I12: Elevated globally | J12: Strategic reductions planned, especially in Greater China.
B13: Puma | C13: 0.7638 | D13: 25.6 | E13: 0.88 | F13: 7.19
B14: Under Armour And V.F. | C14: 0.6958 | D14: 13.11 | E14: 0.52 | F14: 3.6
B16: Averages | C16: =AVERAGE(C7:C14) -> 2.89295 | D16: =AVERAGE(D7:D14) -> 26.28875
A18: Target | B18: Nikes | C18: =PS_Ratio_Competitors*'Updated Sheet'!C25/('Input & Dashboard'!B8/1000000)*4 -> 107.33034 | D18: =PE_Ratio_Competitors*'Updated Sheet'!O25*4 -> 94.070845

Sheet Updated Sheet
A1: Year | B1: Quarter | C1: Revenues | D1: Cost of sales | E1: Gross profit | F1: Net Income | G1: Cash and Equivalents | H1: Total assets | I1: Total Liabilities | J1: Total Shareholders Equity | K1: Gross % | L1: Net % | M1: ROA | N1: ROE | O1: EPS
A2: 2019 | B2: Q1 | C2: 9611 | D2: 5272 | E2: 4339 | F2: 1101 | G2: 3695 | H2: 22921 | I2: =H2-J2 -> 13960 | J2: 8961 | K2: =E2/C2 -> 0.45146187 | L2: =F2/C2 -> 0.11455624 | O2: 0.68
A3: 2019 | B3: Q2 | C3: 8520 | D3: 4800 | E3: 3720 | F3: 446 | G3: 4466 | H3: 23717 | I3: =H3-J3 -> 14677 | J3: 9040 | K3: =E3/C3 -> 0.43661972 | L3: =F3/C3 -> 0.052347418 | M3: =AVERAGE(F2:F3)/H3 -> 0.032613737 | N3: =AVERAGE(F2:F3)/J3 -> 0.085564159 | O3: 0.62
A4: 2019 | B4: Q3 | C4: 10660 | D4: 5789 | E4: 4871 | F4: 1367 | G4: 3446 | H4: 26249 | I4: =H4-J4 -> 17049 | J4: 9200 | K4: =E4/C4 -> 0.45694184 | L4: =F4/C4 -> 0.1282364 | M4: =AVERAGE(F3:F4)/H4 -> 0.034534649 | N4: =AVERAGE(F3:F4)/J4 -> 0.098532609 | O4: 0.86
A5: 2019 | B5: Q4 | C5: 10326 | D5: 5782 | E5: 4544 | F5: 1115 | G5: 3070 | H5: 26602 | I5: =H5-J5 -> 17251 | J5: 9351 | K5: =E5/C5 -> 0.44005423 | L5: =F5/C5 -> 0.10797986 | M5: =AVERAGE(F4:F5)/H5 -> 0.046650628 | N5: =AVERAGE(F4:F5)/J5 -> 0.13271308 | O5: 0.7
A6: 2020 | B6: Q1 | C6: 10104 | D6: 5631 | E6: 4473 | F6: 847 | G6: 2863 | H6: 26220 | I6: =H6-J6 -> 17175 | J6: 9045 | K6: =E6/C6 -> 0.44269596 | L6: =F6/C6 -> 0.083828187 | M6: =AVERAGE(F5:F6)/H6 -> 0.037414188 | N6: =AVERAGE(F5:F6)/J6 -> 0.10845771 | O6: 0.53
A7: 2020 | B7: Q2 | C7: 5462 | D7: 3282 | E7: 2180 | F7: -1077 | G7: 8348 | H7: 31342 | I7: =H7-J7 -> 23287 | J7: 8055 | K7: =E7/C7 -> 0.3991212 | L7: =F7/C7 -> -0.19718052 | M7: =AVERAGE(F6:F7)/H7 -> -0.0036691979 | N7: =AVERAGE(F6:F7)/J7 -> -0.014276847 | O7: -0.49
A8: 2020 | B8: Q3 | C8: 10594 | D8: 5853 | E8: 4741 | F8: 1518 | G8: 8148 | H8: 33258 | I8: =H8-J8 -> 24034 | J8: 9224 | K8: =E8/C8 -> 0.44751746 | L8: =F8/C8 -> 0.14328865 | M8: =AVERAGE(F7:F8)/H8 -> 0.0066299838 | N8: =AVERAGE(F7:F8)/J8 -> 0.02390503 | O8: 0.95
A9: 2020 | B9: Q4 | C9: 11243 | D9: 6396 | E9: 4847 | F9: 1251 | G9: 8635 | H9: 34836 | I9: =H9-J9 -> 24196 | J9: 10640 | K9: =E9/C9 -> 0.43111269 | L9: =F9/C9 -> 0.11126923 | M9: =AVERAGE(F8:F9)/H9 -> 0.039743369 | N9: =AVERAGE(F8:F9)/J9 -> 0.13012218 | O9: 0.78
A10: 2021 | B10: Q1 | C10: 10357 | D10: 5638 | E10: 4719 | F10: 1449 | G10: 8516 | H10: 36185 | I10: =H10-J10 -> 24254 | J10: 11931 | K10: =E10/C10 -> 0.45563387 | L10: =F10/C10 -> 0.13990538 | M10: =AVERAGE(F9:F10)/H10 -> 0.037308277 | N10: =AVERAGE(F9:F10)/J10 -> 0.11315062 | O10: 0.9
A11: 2021 | B11: Q2 | C11: 10576 | D11: 6242 | E11: 4334 | F11: 1067 | G11: 9889 | H11: 37740 | I11: =H11-J11 -> 24973 | J11: 12767 | K11: =E11/C11 -> 0.40979576 | L11: =F11/C11 -> 0.1008888 | M11: =AVERAGE(F10:F11)/H11 -> 0.033333333 | N11: =AVERAGE(F10:F11)/J11 -> 0.098535286 | O11: 0.93
A12: 2021 | B12: Q3 | C12: 12248 | D12: 6552 | E12: 5696 | F12: 1874 | G12: 10720 | H12: 37917 | I12: =H12-J12 -> 23574 | J12: 14343 | K12: =E12/C12 -> 0.46505552 | L12: =F12/C12 -> 0.15300457 | M12: =AVERAGE(F11:F12)/H12 -> 0.038782077 | N12: =AVERAGE(F11:F12)/J12 -> 0.10252388 | O12: 1.16
A13: 2021 | B13: Q4 | C13: 11357 | D13: 6144 | E13: 5213 | F13: 1337 | G13: 10751 | H13: 38917 | I13: =H13-J13 -> 23993 | J13: 14924 | K13: =E13/C13 -> 0.45901206 | L13: =F13/C13 -> 0.11772475 | M13: =AVERAGE(F12:F13)/H13 -> 0.041254465 | N13: =AVERAGE(F12:F13)/J13 -> 0.1075784 | O13: 0.83
A14: 2022 | B14: Q1 | C14: 10871 | D14: 5804 | E14: 5067 | F14: 1396 | G14: 8704 | H14: 38577 | I14: =H14-J14 -> 23768 | J14: 14809 | K14: =E14/C14 -> 0.46610247 | L14: =F14/C14 -> 0.12841505 | M14: =AVERAGE(F13:F14)/H14 -> 0.035422661 | N14: =AVERAGE(F13:F14)/J14 -> 0.092274968 | O14: 0.87
... A24: 2024 | B24: Q3 | C24: 11589 | D24: 6332 | E24: 5257 | F24: 1051 | G24: 8485 | H24: 37867 | I24: =H24-J24 -> 23923 | J24: 13944 | K24: =E24/C24 -> 0.45361981 | L24: =F24/C24 -> 0.090689447 | M24: =AVERAGE(F23:F24)/H24 -> 0.032693374 | N24: =AVERAGE(F23:F24)/J24 -> 0.088783706 | O24: 0.7
A25: 2024 | B25: Q4 | C25: =C24*IF('Input & Dashboard'!B4<>0,(1+'Input & Dashboard'!B4),(1+('Input & Dashboard'!$B$7*Regression!$Q$42)+Regression!$Q$41)) -> 13906.8 | D25: =FORECAST(C25,D$2:D$21,$C$2:$C$21) -> 7729.4156 | E25: =C25-D25 -> 6177.3844 | F25: =C25*L25 -> 1341.3148 | G25: =FORECAST(F25,G$2:G$21,$C$2:$C$21) -> 5182.7824 | H25: =F25/M25 -> 38839.684 | I25: =H25-J25 -> 24303.62 | J25: =F25/N25 -> 14536.064 | K25: =E25/C25 -> 0.44419884 | L25: =AVERAGE(L2:L24) -> 0.096450286 | M25: =MEDIAN(M3:M21) -> 0.034534649 | N25: =MEDIAN(N2:N21) -> 0.092274968 | O25: =F25/('Input & Dashboard'!B8/1000000) -> 0.89459222

Sheet Revenue Detail
A1: YEAR | B1: (Dollars in millions) | C1: NORTH AMERICA | D1: EUROPE, MIDDLE EAST & AFRICA | E1: GREATER CHINA | F1: ASIA PACIFIC & LATIN AMERICA | G1: GLOBAL BRAND DIVISIONS | H1: TOTAL NIKE BRAND | I1: CONVERSE | J1: CORPORATE | K1: TOTAL NIKE, INC.
A2: 2024 | B2: Footwear | C2: 14537 | D2: 8473 | E2: 5552 | F2: 4865 | H2: 33427 | I2: 1800 | K2: 35227 | O2: =VALUE(TRIM(Table2[[#This Row],[GREATER CHINA]])) -> 5552 | P2: =VALUE(TRIM(Table2[[#This Row],[ASIA PACIFIC & LATIN AMERICA]])) -> 4865 | Q2: =VALUE(TRIM(Table2[[#This Row],[GLOBAL BRAND DIVISIONS]])) -> #VALUE! | R2: =VALUE(TRIM(Table2[[#This Row],[TOTAL NIKE BRAND]])) -> 33427 | S2: =VALUE(TRIM(Table2[[#This Row],[CONVERSE]])) -> 1800 | T2: =VALUE(TRIM(Table2[[#This Row],[CORPORATE]])) -> #VALUE! | U2: =VALUE(TRIM(Table2[[#This Row],[TOTAL NIKE, INC.]])) -> 35227
A3: 2024 | B3: Apparel | C3: 5953 | D3: 4380 | E3: 1828 | F3: 1614 | H3: 13775 | I3: 93 | K3: 13868
A4: 2024 | B4: Equipment | C4: 906 | D4: 754 | E4: 165 | F4: 250 | H4: 2075 | I4: 37 | K4: 2112
A5: 2024 | B5: Other | G5: 45 | H5: 45 | I5: 152 | J5: -42 | K5: 155
A6: 2024 | B6: Sales to Wholesale Customers | C6: 11004 | D6: 8562 | E6: 4262 | F6: 3930 | H6: 27758 | I6: 1098 | K6: 28856
A7: 2024 | B7: Sales through Direct to Consumer | C7: 10392 | D7: 5045 | E7: 3283 | F7: 2799 | H7: 21519 | I7: 832 | K7: 22351
A8: 2024 | B8: Other | G8: 45 | H8: 45 | I8: 152 | J8: -42 | K8: 155
A9: 2023 | B9: Footwear | C9: 14897 | D9: 8260 | E9: 5435 | F9: 4543 | H9: 33135 | I9: 2155 | K9: 35290
A10: 2023 | B10: Apparel | C10: 5947 | D10: 4566 | E10: 1666 | F10: 1664 | H10: 13843 | I10: 90 | K10: 13933
A11: 2023 | B11: Equipment | C11: 764 | D11: 592 | E11: 147 | F11: 224 | H11: 1727 | I11: 28 | K11: 1755
A12: 2023 | B12: Other | G12: 58 | H12: 58 | I12: 154 | J12: 27 | K12: 239
A13: 2023 | B13: Sales to Wholesale Customers | C13: 11273 | D13: 8522 | E13: 3866 | F13: 3736 | H13: 27397 | I13: 1299 | K13: 28696
A14: 2023 | B14: Sales through Direct to Consumer | C14: 10335 | D14: 4896 | E14: 3382 | F14: 2695 | H14: 21308 | I14: 974 | K14: 22282
A15: 2023 | B15: Other | G15: 58 | H15: 58 | I15: 154 | J15: 27 | K15: 239
A16: 2022 | B16: Footwear | C16: 12228 | D16: 7388 | E16: 5416 | F16: 4111 | H16: 29143 | I16: 2094 | K16: 31237
A17: 2022 | B17: Apparel | C17: 5492 | D17: 4527 | E17: 1938 | F17: 1610 | H17: 13567 | I17: 103 | K17: 13670
A18: 2022 | B18: Equipment | C18: 633 | D18: 564 | E18: 193 | F18: 234 | H18: 1624 | I18: 26 | K18: 1650
A19: 2022 | B19: Other | G19: 102 | H19: 102 | I19: 123 | J19: -72 | K19: 153
A20: 2022 | B20: Sales to Wholesale Customers | C20: 9621 | D20: 8377 | E20: 4081 | F20: 3529 | H20: 25608 | I20: 1292 | K20: 26900
A21: 2022 | B21: Sales through Direct to Consumer | C21: 8732 | D21: 4102 | E21: 3466 | F21: 2426 | H21: 18726 | I21: 931 | K21: 19657
A22: 2022 | B22: Other | G22: 102 | H22: 102 | I22: 123 | J22: -72 | K22: 153
A25: YEAR | B25: (Dollars in millions) | C25: NORTH AMERICA | D25: EUROPE, MIDDLE EAST & AFRICA | E25: GREATER CHINA | F25: ASIA PACIFIC & LATIN AMERICA | G25: GLOBAL BRAND DIVISIONS | H25: TOTAL NIKE BRAND | I25: CONVERSE | J25: CORPORATE | K25: TOTAL NIKE, INC.
A26: 2024 | B26: Footwear | C26: =C2/SUMIFS(Table2[[#All],[NORTH AMERICA]],Table2[[#All],[YEAR ]:[YEAR ]],$A26) -> 0.33971303 | D26: =D2/SUMIFS(Table2[[#All],[EUROPE, MIDDLE EAST & AFRICA]],Table2[[#All],[YEAR ]:[YEAR ]],$A26) -> 0.3113471 | E26: =E2/SUMIFS(Table2[[#All],[GREATER CHINA]],Table2[[#All],[YEAR ]:[YEAR ]],$A26) -> 0.36792578 | F26: =F2/SUMIFS(Table2[[#All],[ASIA PACIFIC & LATIN AMERICA]],Table2[[#All],[YEAR ]:[YEAR ]],$A26) -> 0.36149502 | G26: =G2/SUMIFS(Table2[[#All],[GLOBAL BRAND DIVISIONS]],Table2[[#All],[YEAR ]:[YEAR ]],$A26) -> 0 | H26: =H2/SUMIFS(Table2[[#All],[TOTAL NIKE BRAND]],Table2[[#All],[YEAR ]:[YEAR ]],$A26) -> 0.33886501 | I26: =I2/SUMIFS(Table2[[#All],[CONVERSE]],Table2[[#All],[YEAR ]:[YEAR ]],$A26) -> 0.43227666 | J26: =J2/SUMIFS(Table2[[#All],[CORPORATE]],Table2[[#All],[YEAR ]:[YEAR ]],$A26) -> 0 | K26: =K2/SUMIFS(Table2[[#All],[TOTAL NIKE, INC.]],Table2[[#All],[YEAR ]:[YEAR ]],$A26) -> 0.34292862
A27: 2024 | B27: Apparel | C27: =C3/SUMIFS(Table2[[#All],[NORTH AMERICA]],Table2[[#All],[YEAR ]:[YEAR ]],$A27) -> 0.13911479 | D27: =D3/SUMIFS(Table2[[#All],[EUROPE, MIDDLE EAST & AFRICA]],Table2[[#All],[YEAR ]:[YEAR ]],$A27) -> 0.16094657 | E27: =E3/SUMIFS(Table2[[#All],[GREATER CHINA]],Table2[[#All],[YEAR ]:[YEAR ]],$A27) -> 0.12113983 | F27: =F3/SUMIFS(Table2[[#All],[ASIA PACIFIC & LATIN AMERICA]],Table2[[#All],[YEAR ]:[YEAR ]],$A27) -> 0.11992867 | G27: =G3/SUMIFS(Table2[[#All],[GLOBAL BRAND DIVISIONS]],Table2[[#All],[YEAR ]:[YEAR ]],$A27) -> 0 | H27: =H3/SUMIFS(Table2[[#All],[TOTAL NIKE BRAND]],Table2[[#All],[YEAR ]:[YEAR ]],$A27) -> 0.13964357 | I27: =I3/SUMIFS(Table2[[#All],[CONVERSE]],Table2[[#All],[YEAR ]:[YEAR ]],$A27) -> 0.022334294 | J27: =J3/SUMIFS(Table2[[#All],[CORPORATE]],Table2[[#All],[YEAR ]:[YEAR ]],$A27) -> 0 | K27: =K3/SUMIFS(Table2[[#All],[TOTAL NIKE, INC.]],Table2[[#All],[YEAR ]:[YEAR ]],$A27) -> 0.13500253
A28: 2024 | B28: Equipment | C28: =C4/SUMIFS(Table2[[#All],[NORTH AMERICA]],Table2[[#All],[YEAR ]:[YEAR ]],$A28) -> 0.021172182 | D28: =D4/SUMIFS(Table2[[#All],[EUROPE, MIDDLE EAST & AFRICA]],Table2[[#All],[YEAR ]:[YEAR ]],$A28) -> 0.027706328 | E28: =E4/SUMIFS(Table2[[#All],[GREATER CHINA]],Table2[[#All],[YEAR ]:[YEAR ]],$A28) -> 0.010934394 | F28: =F4/SUMIFS(Table2[[#All],[ASIA PACIFIC & LATIN AMERICA]],Table2[[#All],[YEAR ]:[YEAR ]],$A28) -> 0.018576311 | G28: =G4/SUMIFS(Table2[[#All],[GLOBAL BRAND DIVISIONS]],Table2[[#All],[YEAR ]:[YEAR ]],$A28) -> 0 | H28: =H4/SUMIFS(Table2[[#All],[TOTAL NIKE BRAND]],Table2[[#All],[YEAR ]:[YEAR ]],$A28) -> 0.021035238 | I28: =I4/SUMIFS(Table2[[#All],[CONVERSE]],Table2[[#All],[YEAR ]:[YEAR ]],$A28) -> 0.0088856868 | J28: =J4/SUMIFS(Table2[[#All],[CORPORATE]],Table2[[#All],[YEAR ]:[YEAR ]],$A28) -> 0 | K28: =K4/SUMIFS(Table2[[#All],[TOTAL NIKE, INC.]],Table2[[#All],[YEAR ]:[YEAR ]],$A28) -> 0.020559947
A29: 2024 | B29: Other | C29: =C5/SUMIFS(Table2[[#All],[NORTH AMERICA]],Table2[[#All],[YEAR ]:[YEAR ]],$A29) -> 0 | D29: =D5/SUMIFS(Table2[[#All],[EUROPE, MIDDLE EAST & AFRICA]],Table2[[#All],[YEAR ]:[YEAR ]],$A29) -> 0 | E29: =E5/SUMIFS(Table2[[#All],[GREATER CHINA]],Table2[[#All],[YEAR ]:[YEAR ]],$A29) -> 0 | F29: =F5/SUMIFS(Table2[[#All],[ASIA PACIFIC & LATIN AMERICA]],Table2[[#All],[YEAR ]:[YEAR ]],$A29) -> 0 | G29: =G5/SUMIFS(Table2[[#All],[GLOBAL BRAND DIVISIONS]],Table2[[#All],[YEAR ]:[YEAR ]],$A29) -> 0.5 | H29: =H5/SUMIFS(Table2[[#All],[TOTAL NIKE BRAND]],Table2[[#All],[YEAR ]:[YEAR ]],$A29) -> 0.00045618588 | I29: =I5/SUMIFS(Table2[[#All],[CONVERSE]],Table2[[#All],[YEAR ]:[YEAR ]],$A29) -> 0.036503362 | J29: =J5/SUMIFS(Table2[[#All],[CORPORATE]],Table2[[#All],[YEAR ]:[YEAR ]],$A29) -> 0.5 | K29: =K5/SUMIFS(Table2[[#All],[TOTAL NIKE, INC.]],Table2[[#All],[YEAR ]:[YEAR ]],$A29) -> 0.0015088976
A30: 2024 | B30: Sales to Wholesale Customers | C30: =C6/SUMIFS(Table2[[#All],[NORTH AMERICA]],Table2[[#All],[YEAR ]:[YEAR ]],$A30) -> 0.25715087 | D30: =D6/SUMIFS(Table2[[#All],[EUROPE, MIDDLE EAST & AFRICA]],Table2[[#All],[YEAR ]:[YEAR ]],$A30) -> 0.31461748 | E30: =E6/SUMIFS(Table2[[#All],[GREATER CHINA]],Table2[[#All],[YEAR ]:[YEAR ]],$A30) -> 0.2824387 | F30: =F6/SUMIFS(Table2[[#All],[ASIA PACIFIC & LATIN AMERICA]],Table2[[#All],[YEAR ]:[YEAR ]],$A30) -> 0.29201962 | G30: =G6/SUMIFS(Table2[[#All],[GLOBAL BRAND DIVISIONS]],Table2[[#All],[YEAR ]:[YEAR ]],$A30) -> 0 | H30: =H6/SUMIFS(Table2[[#All],[TOTAL NIKE BRAND]],Table2[[#All],[YEAR ]:[YEAR ]],$A30) -> 0.28139573 | I30: =I6/SUMIFS(Table2[[#All],[CONVERSE]],Table2[[#All],[YEAR ]:[YEAR ]],$A30) -> 0.26368876 | J30: =J6/SUMIFS(Table2[[#All],[CORPORATE]],Table2[[#All],[YEAR ]:[YEAR ]],$A30) -> 0 | K30: =K6/SUMIFS(Table2[[#All],[TOTAL NIKE, INC.]],Table2[[#All],[YEAR ]:[YEAR ]],$A30) -> 0.28090806
A31: 2024 | B31: Sales through Direct to Consumer | C31: =C7/SUMIFS(Table2[[#All],[NORTH AMERICA]],Table2[[#All],[YEAR ]:[YEAR ]],$A31) -> 0.24284913 | D31: =D7/SUMIFS(Table2[[#All],[EUROPE, MIDDLE EAST & AFRICA]],Table2[[#All],[YEAR ]:[YEAR ]],$A31) -> 0.18538252 | E31: =E7/SUMIFS(Table2[[#All],[GREATER CHINA]],Table2[[#All],[YEAR ]:[YEAR ]],$A31) -> 0.2175613 | F31: =F7/SUMIFS(Table2[[#All],[ASIA PACIFIC & LATIN AMERICA]],Table2[[#All],[YEAR ]:[YEAR ]],$A31) -> 0.20798038 | G31: =G7/SUMIFS(Table2[[#All],[GLOBAL BRAND DIVISIONS]],Table2[[#All],[YEAR ]:[YEAR ]],$A31) -> 0 | H31: =H7/SUMIFS(Table2[[#All],[TOTAL NIKE BRAND]],Table2[[#All],[YEAR ]:[YEAR ]],$A31) -> 0.21814809 | I31: =I7/SUMIFS(Table2[[#All],[CONVERSE]],Table2[[#All],[YEAR ]:[YEAR ]],$A31) -> 0.19980788 | J31: =J7/SUMIFS(Table2[[#All],[CORPORATE]],Table2[[#All],[YEAR ]:[YEAR ]],$A31) -> 0 | K31: =K7/SUMIFS(Table2[[#All],[TOTAL NIKE, INC.]],Table2[[#All],[YEAR ]:[YEAR ]],$A31) -> 0.21758304
A32: 2024 | B32: Other | C32: =C8/SUMIFS(Table2[[#All],[NORTH AMERICA]],Table2[[#All],[YEAR ]:[YEAR ]],$A32) -> 0 | D32: =D8/SUMIFS(Table2[[#All],[EUROPE, MIDDLE EAST & AFRICA]],Table2[[#All],[YEAR ]:[YEAR ]],$A32) -> 0 | E32: =E8/SUMIFS(Table2[[#All],[GREATER CHINA]],Table2[[#All],[YEAR ]:[YEAR ]],$A32) -> 0 | F32: =F8/SUMIFS(Table2[[#All],[ASIA PACIFIC & LATIN AMERICA]],Table2[[#All],[YEAR ]:[YEAR ]],$A32) -> 0 | G32: =G8/SUMIFS(Table2[[#All],[GLOBAL BRAND DIVISIONS]],Table2[[#All],[YEAR ]:[YEAR ]],$A32) -> 0.5 | H32: =H8/SUMIFS(Table2[[#All],[TOTAL NIKE BRAND]],Table2[[#All],[YEAR ]:[YEAR ]],$A32) -> 0.00045618588 | I32: =I8/SUMIFS(Table2[[#All],[CONVERSE]],Table2[[#All],[YEAR ]:[YEAR ]],$A32) -> 0.036503362 | J32: =J8/SUMIFS(Table2[[#All],[CORPORATE]],Table2[[#All],[YEAR ]:[YEAR ]],$A32) -> 0.5 | K32: =K8/SUMIFS(Table2[[#All],[TOTAL NIKE, INC.]],Table2[[#All],[YEAR ]:[YEAR ]],$A32) -> 0.0015088976
A33: 2023 | B33: Footwear | C33: =C9/SUMIFS(Table2[[#All],[NORTH AMERICA]],Table2[[#All],[YEAR ]:[YEAR ]],$A33) -> 0.34471029 | D33: =D9/SUMIFS(Table2[[#All],[EUROPE, MIDDLE EAST & AFRICA]],Table2[[#All],[YEAR ]:[YEAR ]],$A33) -> 0.3077955 | E33: =E9/SUMIFS(Table2[[#All],[GREATER CHINA]],Table2[[#All],[YEAR ]:[YEAR ]],$A33) -> 0.37493102 | F33: =F9/SUMIFS(Table2[[#All],[ASIA PACIFIC & LATIN AMERICA]],Table2[[#All],[YEAR ]:[YEAR ]],$A33) -> 0.35321101 | G33: =G9/SUMIFS(Table2[[#All],[GLOBAL BRAND DIVISIONS]],Table2[[#All],[YEAR ]:[YEAR ]],$A33) -> 0 | H33: =H9/SUMIFS(Table2[[#All],[TOTAL NIKE BRAND]],Table2[[#All],[YEAR ]:[YEAR ]],$A33) -> 0.33975555 | I33: =I9/SUMIFS(Table2[[#All],[CONVERSE]],Table2[[#All],[YEAR ]:[YEAR ]],$A33) -> 0.44396374 | J33: =J9/SUMIFS(Table2[[#All],[CORPORATE]],Table2[[#All],[YEAR ]:[YEAR ]],$A33) -> 0 | K33: =K9/SUMIFS(Table2[[#All],[TOTAL NIKE, INC.]],Table2[[#All],[YEAR ]:[YEAR ]],$A33) -> 0.34451452
A34: 2023 | B34: Apparel | C34: =C10/SUMIFS(Table2[[#All],[NORTH AMERICA]],Table2[[#All],[YEAR ]:[YEAR ]],$A34) -> 0.13761107 | D34: =D10/SUMIFS(Table2[[#All],[EUROPE, MIDDLE EAST & AFRICA]],Table2[[#All],[YEAR ]:[YEAR ]],$A34) -> 0.17014458 | E34: =E10/SUMIFS(Table2[[#All],[GREATER CHINA]],Table2[[#All],[YEAR ]:[YEAR ]],$A34) -> 0.11492826 | F34: =F10/SUMIFS(Table2[[#All],[ASIA PACIFIC & LATIN AMERICA]],Table2[[#All],[YEAR ]:[YEAR ]],$A34) -> 0.12937335 | G34: =G10/SUMIFS(Table2[[#All],[GLOBAL BRAND DIVISIONS]],Table2[[#All],[YEAR ]:[YEAR ]],$A34) -> 0 | H34: =H10/SUMIFS(Table2[[#All],[TOTAL NIKE BRAND]],Table2[[#All],[YEAR ]:[YEAR ]],$A34) -> 0.14194164 | I34: =I10/SUMIFS(Table2[[#All],[CONVERSE]],Table2[[#All],[YEAR ]:[YEAR ]],$A34) -> 0.018541409 | J34: =J10/SUMIFS(Table2[[#All],[CORPORATE]],Table2[[#All],[YEAR ]:[YEAR ]],$A34) -> 0 | K34: =K10/SUMIFS(Table2[[#All],[TOTAL NIKE, INC.]],Table2[[#All],[YEAR ]:[YEAR ]],$A34) -> 0.13601929
A35: 2023 | B35: Equipment | C35: =C11/SUMIFS(Table2[[#All],[NORTH AMERICA]],Table2[[#All],[YEAR ]:[YEAR ]],$A35) -> 0.017678638 | D35: =D11/SUMIFS(Table2[[#All],[EUROPE, MIDDLE EAST & AFRICA]],Table2[[#All],[YEAR ]:[YEAR ]],$A35) -> 0.02205992 | E35: =E11/SUMIFS(Table2[[#All],[GREATER CHINA]],Table2[[#All],[YEAR ]:[YEAR ]],$A35) -> 0.010140728 | F35: =F11/SUMIFS(Table2[[#All],[ASIA PACIFIC & LATIN AMERICA]],Table2[[#All],[YEAR ]:[YEAR ]],$A35) -> 0.017415643 | G35: =G11/SUMIFS(Table2[[#All],[GLOBAL BRAND DIVISIONS]],Table2[[#All],[YEAR ]:[YEAR ]],$A35) -> 0 | H35: =H11/SUMIFS(Table2[[#All],[TOTAL NIKE BRAND]],Table2[[#All],[YEAR ]:[YEAR ]],$A35) -> 0.017708098 | I35: =I11/SUMIFS(Table2[[#All],[CONVERSE]],Table2[[#All],[YEAR ]:[YEAR ]],$A35) -> 0.0057684384 | J35: =J11/SUMIFS(Table2[[#All],[CORPORATE]],Table2[[#All],[YEAR ]:[YEAR ]],$A35) -> 0 | K35: =K11/SUMIFS(Table2[[#All],[TOTAL NIKE, INC.]],Table2[[#All],[YEAR ]:[YEAR ]],$A35) -> 0.017132983
A36: 2023 | B36: Other | C36: =C12/SUMIFS(Table2[[#All],[NORTH AMERICA]],Table2[[#All],[YEAR ]:[YEAR ]],$A36) -> 0 | D36: =D12/SUMIFS(Table2[[#All],[EUROPE, MIDDLE EAST & AFRICA]],Table2[[#All],[YEAR ]:[YEAR ]],$A36) -> 0 | E36: =E12/SUMIFS(Table2[[#All],[GREATER CHINA]],Table2[[#All],[YEAR ]:[YEAR ]],$A36) -> 0 | F36: =F12/SUMIFS(Table2[[#All],[ASIA PACIFIC & LATIN AMERICA]],Table2[[#All],[YEAR ]:[YEAR ]],$A36) -> 0 | G36: =G12/SUMIFS(Table2[[#All],[GLOBAL BRAND DIVISIONS]],Table2[[#All],[YEAR ]:[YEAR ]],$A36) -> 0.5 | H36: =H12/SUMIFS(Table2[[#All],[TOTAL NIKE BRAND]],Table2[[#All],[YEAR ]:[YEAR ]],$A36) -> 0.0005947132 | I36: =I12/SUMIFS(Table2[[#All],[CONVERSE]],Table2[[#All],[YEAR ]:[YEAR ]],$A36) -> 0.031726411 | J36: =J12/SUMIFS(Table2[[#All],[CORPORATE]],Table2[[#All],[YEAR ]:[YEAR ]],$A36) -> 0.5 | K36: =K12/SUMIFS(Table2[[#All],[TOTAL NIKE, INC.]],Table2[[#All],[YEAR ]:[YEAR ]],$A36) -> 0.0023332097
A37: 2023 | B37: Sales to Wholesale Customers | C37: =C13/SUMIFS(Table2[[#All],[NORTH AMERICA]],Table2[[#All],[YEAR ]:[YEAR ]],$A37) -> 0.26085246 | D37: =D13/SUMIFS(Table2[[#All],[EUROPE, MIDDLE EAST & AFRICA]],Table2[[#All],[YEAR ]:[YEAR ]],$A37) -> 0.3175585 | E37: =E13/SUMIFS(Table2[[#All],[GREATER CHINA]],Table2[[#All],[YEAR ]:[YEAR ]],$A37) -> 0.26669426 | F37: =F13/SUMIFS(Table2[[#All],[ASIA PACIFIC & LATIN AMERICA]],Table2[[#All],[YEAR ]:[YEAR ]],$A37) -> 0.29046805 | G37: =G13/SUMIFS(Table2[[#All],[GLOBAL BRAND DIVISIONS]],Table2[[#All],[YEAR ]:[YEAR ]],$A37) -> 0 | H37: =H13/SUMIFS(Table2[[#All],[TOTAL NIKE BRAND]],Table2[[#All],[YEAR ]:[YEAR ]],$A37) -> 0.28091996 | I37: =I13/SUMIFS(Table2[[#All],[CONVERSE]],Table2[[#All],[YEAR ]:[YEAR ]],$A37) -> 0.26761434 | J37: =J13/SUMIFS(Table2[[#All],[CORPORATE]],Table2[[#All],[YEAR ]:[YEAR ]],$A37) -> 0 | K37: =K13/SUMIFS(Table2[[#All],[TOTAL NIKE, INC.]],Table2[[#All],[YEAR ]:[YEAR ]],$A37) -> 0.28014136
... A46: 2022 | B46: Other | C46: =C22/SUMIFS(Table2[[#All],[NORTH AMERICA]],Table2[[#All],[YEAR ]:[YEAR ]],$A46) -> 0 | D46: =D22/SUMIFS(Table2[[#All],[EUROPE, MIDDLE EAST & AFRICA]],Table2[[#All],[YEAR ]:[YEAR ]],$A46) -> 0 | E46: =E22/SUMIFS(Table2[[#All],[GREATER CHINA]],Table2[[#All],[YEAR ]:[YEAR ]],$A46) -> 0 | F46: =F22/SUMIFS(Table2[[#All],[ASIA PACIFIC & LATIN AMERICA]],Table2[[#All],[YEAR ]:[YEAR ]],$A46) -> 0 | G46: =G22/SUMIFS(Table2[[#All],[GLOBAL BRAND DIVISIONS]],Table2[[#All],[YEAR ]:[YEAR ]],$A46) -> 0.5 | H46: =H22/SUMIFS(Table2[[#All],[TOTAL NIKE BRAND]],Table2[[#All],[YEAR ]:[YEAR ]],$A46) -> 0.0011477181 | I46: =I22/SUMIFS(Table2[[#All],[CONVERSE]],Table2[[#All],[YEAR ]:[YEAR ]],$A46) -> 0.026214834 | J46: =J22/SUMIFS(Table2[[#All],[CORPORATE]],Table2[[#All],[YEAR ]:[YEAR ]],$A46) -> 0.5 | K46: =K22/SUMIFS(Table2[[#All],[TOTAL NIKE, INC.]],Table2[[#All],[YEAR ]:[YEAR ]],$A46) -> 0.0016377649

Sheet Regression
A1: Series ID | B1: Year | C1: Period | D1: Label | E1: Value
A2: CWUR0000SA0 | B2: 2018 | C2: M01 | D2: 2018 Jan | E2: 241.919 | H2: Year | I2: Revenue | J2: cpi | L2: Revenue growth | M2: Inflation rate | P2: SUMMARY OUTPUT
A3: CWUR0000SA0 | B3: 2018 | C3: M02 | D3: 2018 Feb | E3: 242.988 | G3: 245.14633 | H3: 2019 | I3: =SUMIFS('Updated Sheet'!$C$1:$C$21,'Updated Sheet'!$A$1:$A$21,Regression!H3) -> 39117 | J3: =AVERAGEIF($B:$B,H3,$E:$E) -> 249.2215 | L3: 0.09 | M3: =J3/G3-1 -> 0.016623405
A4: CWUR0000SA0 | B4: 2018 | C4: M03 | D4: 2018 Mar | E4: 243.463 | H4: 2020 | I4: =SUMIFS('Updated Sheet'!$C$1:$C$21,'Updated Sheet'!$A$1:$A$21,Regression!H4) -> 37403 | J4: =AVERAGEIF($B:$B,H4,$E:$E) -> 252.24842 | L4: =I6/I5-1 -> 0.048767345 | M4: =J6/J5-1 -> 0.084645066 | P4: Regression Statistics
A5: CWUR0000SA0 | B5: 2018 | C5: M04 | D5: 2018 Apr | E5: 244.607 | H5: 2021 | I5: =SUMIFS('Updated Sheet'!$C$1:$C$21,'Updated Sheet'!$A$1:$A$21,Regression!H5) -> 44538 | J5: =AVERAGEIF($B:$B,H5,$E:$E) -> 265.50967 | L5: =I7/I6-1 -> 0.096488975 | M5: =J7/J6-1 -> 0.038218013 | P5: Multiple R | Q5: 0.24309401
A6: CWUR0000SA0 | B6: 2018 | C6: M05 | D6: 2018 May | E6: 245.77 | H6: 2022 | I6: =SUMIFS('Updated Sheet'!$C$1:$C$21,'Updated Sheet'!$A$1:$A$21,Regression!H6) -> 46710 | J6: =AVERAGEIF($B:$B,H6,$E:$E) -> 287.98375 | P6: R Square | Q6: 0.059094696
A7: CWUR0000SA0 | B7: 2018 | C7: M06 | D7: 2018 Jun | E7: 246.196 | H7: 2023 | I7: =SUMIFS('Updated Sheet'!$C$1:$C$21,'Updated Sheet'!$A$1:$A$21,Regression!H7) -> 51217 | J7: =AVERAGEIF($B:$B,H7,$E:$E) -> 298.98992 | L7: =I8/I7-1 -> -1 | M7: =J8/J7-1 -> 0.028176358 | P7: Adjusted R Square | Q7: -0.17613163
A8: CWUR0000SA0 | B8: 2018 | C8: M07 | D8: 2018 Jul | E8: 246.155 | H8: 2024 | I8: =SUMIFS('Updated Sheet'!$C$1:$C$21,'Updated Sheet'!$A$1:$A$21,Regression!H8) -> 0 | J8: =AVERAGEIF($B:$B,H8,$E:$E) -> 307.41436 | P8: Standard Error | Q8: 0.48366207
A9: CWUR0000SA0 | B9: 2018 | C9: M08 | D9: 2018 Aug | E9: 246.336 | P9: Observations | Q9: 6
A10: CWUR0000SA0 | B10: 2018 | C10: M09 | D10: 2018 Sep | E10: 246.565 | L10: =I4/I3-1 -> -0.043817266 | M10: =J4/J3-1 -> 0.012145488
A11: CWUR0000SA0 | B11: 2018 | C11: M10 | D11: 2018 Oct | E11: 247.038 | L11: =I5/I4-1 -> 0.1907601 | M11: =J5/J4-1 -> 0.052572183 | P11: ANOVA
A12: CWUR0000SA0 | B12: 2018 | C12: M11 | D12: 2018 Nov | E12: 245.933 | Q12: df | R12: SS | S12: MS | T12: F | U12: Significance F
A13: CWUR0000SA0 | B13: 2018 | C13: M12 | D13: 2018 Dec | E13: 244.786 | P13: Regression | Q13: 1 | R13: 0.058768774 | S13: 0.058768774 | T13: 0.25122484 | U13: 0.64254177
A14: CWUR0000SA0 | B14: 2019 | C14: M01 | D14: 2019 Jan | E14: 245.133 | P14: Residual | Q14: 4 | R14: 0.93571599 | S14: 0.233929
A15: CWUR0000SA0 | B15: 2019 | C15: M02 | D15: 2019 Feb | E15: 246.218 | P15: Total | Q15: 5 | R15: 0.99448476
A16: CWUR0000SA0 | B16: 2019 | C16: M03 | D16: 2019 Mar | E16: 247.768
A17: CWUR0000SA0 | B17: 2019 | C17: M04 | D17: 2019 Apr | E17: 249.332 | Q17: Coefficients | R17: Standard Error | S17: t Stat | T17: P-value | U17: Lower 95% | V17: Upper 95% | W17: Lower 95.0% | X17: Upper 95.0%
A18: CWUR0000SA0 | B18: 2019 | C18: M05 | D18: 2019 May | E18: 249.871 | P18: Intercept | Q18: -0.25930173 | R18: 0.36915303 | S18: -0.70242341 | T18: 0.52113994 | U18: -1.2842349 | V18: 0.7656314 | W18: -1.2842349 | X18: 0.7656314
A19: CWUR0000SA0 | B19: 2019 | C19: M06 | D19: 2019 Jun | E19: 249.747 | P19: Inflation rate | Q19: 4.0365241 | R19: 8.0533442 | S19: 0.50122334 | T19: 0.64254177 | U19: -18.323144 | V19: 26.396192 | W19: -18.323144 | X19: 26.396192
A20: CWUR0000SA0 | B20: 2019 | C20: M07 | D20: 2019 Jul | E20: 250.236
A21: CWUR0000SA0 | B21: 2019 | C21: M08 | D21: 2019 Aug | E21: 250.112
A22: CWUR0000SA0 | B22: 2019 | C22: M09 | D22: 2019 Sep | E22: 250.251
A23: CWUR0000SA0 | B23: 2019 | C23: M10 | D23: 2019 Oct | E23: 250.894
A24: CWUR0000SA0 | B24: 2019 | C24: M11 | D24: 2019 Nov | E24: 250.644
A25: CWUR0000SA0 | B25: 2019 | C25: M12 | D25: 2019 Dec | E25: 250.452 | P25: SUMMARY OUTPUT
A26: CWUR0000SA0 | B26: 2020 | C26: M01 | D26: 2020 Jan | E26: 251.361
A27: CWUR0000SA0 | B27: 2020 | C27: M02 | D27: 2020 Feb | E27: 251.935 | P27: Regression Statistics
A28: CWUR0000SA0 | B28: 2020 | C28: M03 | D28: 2020 Mar | E28: 251.375 | P28: Multiple R | Q28: 0.90409022
A29: CWUR0000SA0 | B29: 2020 | C29: M04 | D29: 2020 Apr | E29: 249.515 | P29: R Square | Q29: 0.81737912
A30: CWUR0000SA0 | B30: 2020 | C30: M05 | D30: 2020 May | E30: 249.521 | P30: Adjusted R Square | Q30: 0.63475824
A31: CWUR0000SA0 | B31: 2020 | C31: M06 | D31: 2020 Jun | E31: 251.054 | P31: Standard Error | Q31: 0.01564248
A32: CWUR0000SA0 | B32: 2020 | C32: M07 | D32: 2020 Jul | E32: 252.636 | P32: Observations | Q32: 3
A33: CWUR0000SA0 | B33: 2020 | C33: M08 | D33: 2020 Aug | E33: 253.597
A34: CWUR0000SA0 | B34: 2020 | C34: M09 | D34: 2020 Sep | E34: 254.004 | P34: ANOVA
A35: CWUR0000SA0 | B35: 2020 | C35: M10 | D35: 2020 Oct | E35: 254.076 | Q35: df | R35: SS | S35: MS | T35: F | U35: Significance F
A36: CWUR0000SA0 | B36: 2020 | C36: M11 | D36: 2020 Nov | E36: 253.826 | P36: Regression | Q36: 1 | R36: 0.001095177 | S36: 0.001095177 | T36: 4.4758252 | U36: 0.28109969
A37: CWUR0000SA0 | B37: 2020 | C37: M12 | D37: 2020 Dec | E37: 254.081 | P37: Residual | Q37: 1 | R37: 0.00024468718 | S37: 0.00024468718
A38: CWUR0000SA0 | B38: 2021 | C38: M01 | D38: 2021 Jan | E38: 255.296 | P38: Total | Q38: 2 | R38: 0.0013398642
A39: CWUR0000SA0 | B39: 2021 | C39: M02 | D39: 2021 Feb | E39: 256.843
A40: CWUR0000SA0 | B40: 2021 | C40: M03 | D40: 2021 Mar | E40: 258.935 | Q40: Coefficients | R40: Standard Error | S40: t Stat | T40: P-value | U40: Lower 95% | V40: Upper 95% | W40: Lower 95.0% | X40: Upper 95.0%
...

Sheet Sheet2
A2: YEAR | B2: 2024
A4: Row Labels | B4: Sum of NORTH AMERICA | C4: Sum of EUROPE, MIDDLE EAST & AFRICA | D4: Sum of GREATER CHINA | E4: Sum of ASIA PACIFIC & LATIN AMERICA
A5: Apparel | B5: 0.13911479 | C5: 0.16094657 | D5: 0.12113983 | E5: 0.11992867
A6: Equipment | B6: 0.021172182 | C6: 0.027706328 | D6: 0.010934394 | E6: 0.018576311
A7: Footwear | B7: 0.33971303 | C7: 0.3113471 | D7: 0.36792578 | E7: 0.36149502
A8: Other | B8: 0 | C8: 0 | D8: 0 | E8: 0
A9: Sales through Direct to Consumer | B9: 0.24284913 | C9: 0.18538252 | D9: 0.2175613 | E9: 0.20798038
A10: Sales to Wholesale Customers | B10: 0.25715087 | C10: 0.31461748 | D10: 0.2824387 | E10: 0.29201962
A11: Grand Total | B11: 1 | C11: 1 | D11: 1 | E11: 1

Sheet Sheet3
A1: YEAR | B1: (All)
A3: Row Labels | B3: Sum of CONVERSE
A4: Apparel | B4: 286
A5: Equipment | B5: 91
A6: Footwear | B6: 6049
A7: Other | B7: 858
A8: Sales through Direct to Consumer | B8: 2737
A9: Sales to Wholesale Customers | B9: 3689
A10: Grand Total | B10: 13710

Sheet Income Statement
A1: Particulars | B1: Quarter/Year | C1: 2019 | D1: 2020 | E1: 2021 | F1: 2022 | G1: 2023
A2: Revenues | B2: Q1 | C2: 9611 | D2: 10104 | E2: 10357 | F2: 10871 | G2: 12390
A3: Cost of sales | B3: Q1 | C3: 5272 | D3: 5631 | E3: 5638 | F3: 5804 | G3: 7019
A4: Gross profit | B4: Q1 | C4: 4339 | D4: 4473 | E4: 4719 | F4: 5067 | G4: 5371
A5: Demand creation expense | B5: Q1 | C5: 865 | D5: 870 | E5: 711 | F5: 854 | G5: 923
A6: Operating overhead expense | B6: Q1 | C6: 2226 | D6: 2413 | E6: 2330 | F6: 2584 | G6: 3036
A7: Total selling and administrative expense | B7: Q1 | C7: 3091 | D7: 3283 | E7: 3041 | F7: 3438 | G7: 3959
A8: Interest expense (income), net | B8: Q1 | C8: 12 | D8: 12 | E8: 64 | F8: 53 | G8: -7
A9: Other (income) expense, net | B9: Q1 | C9: -55 | D9: 297 | E9: -22 | F9: -94 | G9: -58
A10: Income before income taxes | B10: Q1 | C10: 1291 | D10: 881 | E10: 1636 | F10: 1670 | G10: 1477
A11: Income tax expense | B11: Q1 | C11: 190 | D11: 34 | E11: 187 | F11: 274 | G11: 237
A12: NET INCOME (LOSS) | B12: Q1 | C12: 1101 | D12: 847 | E12: 1449 | F12: 1396 | G12: 1240
... A16: Diluted (in shares) | B16: Q1 | C16: 1609.6 | D16: 1591.6 | E16: 1616.9 | F16: 1610.7 | G16: 1564.8
A17: Revenues | B17: Q2 | C17: =Sheet1!B2-(C2+C32+C47) -> 8520 | D17: =Sheet1!C2-(D2+D32+D47) -> 5462 | E17: =Sheet1!D2-(E2+E32+E47) -> 10576 | F17: =Sheet1!E2-(F2+F32+F47) -> 9837 | G17: =Sheet1!F2-(G2+G32+G47) -> 12500
A18: Cost of sales | B18: Q2 | C18: =Sheet1!B3-(C3+C33+C48) -> 4800 | D18: =Sheet1!C3-(D3+D33+D48) -> 3282 | E18: =Sheet1!D3-(E3+E33+E48) -> 6242 | F18: =Sheet1!E3-(F3+F33+F48) -> 4751 | G18: =Sheet1!F3-(G3+G33+G48) -> 7270
A19: Gross profit | B19: Q2 | C19: =Sheet1!B4-(C4+C34+C49) -> 3720 | D19: =Sheet1!C4-(D4+D34+D49) -> 2180 | E19: =Sheet1!D4-(E4+E34+E49) -> 4334 | F19: =Sheet1!E4-(F4+F34+F49) -> 5086 | G19: =Sheet1!F4-(G4+G34+G49) -> 5230
A20: Demand creation expense | B20: Q2 | C20: =Sheet1!B5-(C5+C35+C50) -> 989 | D20: =Sheet1!C5-(D5+D35+D50) -> 1316 | E20: =Sheet1!D5-(E5+E35+E50) -> 468 | F20: =Sheet1!E5-(F5+F35+F50) -> 951 | G20: =Sheet1!F5-(G5+G35+G50) -> 954
A21: Operating overhead expense | B21: Q2 | C21: =Sheet1!B6-(C6+C36+C51) -> 1970 | D21: =Sheet1!C6-(D6+D36+D51) -> 2285 | E21: =Sheet1!D6-(E6+E36+E51) -> 2185 | F21: =Sheet1!E6-(F6+F36+F51) -> 2371 | G21: =Sheet1!F6-(G6+G36+G51) -> 3202
A22: Total selling and administrative expense | B22: Q2 | C22: =Sheet1!B7-(C7+C37+C52) -> 2959 | D22: =Sheet1!C7-(D7+D37+D52) -> 3601 | E22: =Sheet1!D7-(E7+E37+E52) -> 2653 | F22: =Sheet1!E7-(F7+F37+F52) -> 3322 | G22: =Sheet1!F7-(G7+G37+G52) -> 4156
A23: Interest expense (income), net | B23: Q2 | C23: =Sheet1!B8-(C8+C38+C53) -> 10 | D23: =Sheet1!C8-(D8+D38+D53) -> -58 | E23: =Sheet1!D8-(E8+E38+E53) -> 86 | F23: =Sheet1!E8-(F8+F38+F53) -> 123 | G23: =Sheet1!F8-(G8+G38+G53) -> 57
A24: Other (income) expense, net | B24: Q2 | C24: =Sheet1!B9-(C9+C39+C54) -> 51 | D24: =Sheet1!C9-(D9+D39+D54) -> -198 | E24: =Sheet1!D9-(E9+E39+E54) -> 177 | F24: =Sheet1!E9-(F9+F39+F54) -> 138 | G24: =Sheet1!F9-(G9+G39+G54) -> -137
A25: Income before income taxes | B25: Q2 | C25: =Sheet1!B10-(C10+C40+C55) -> 700 | D25: =Sheet1!C10-(D10+D40+D55) -> -1165 | E25: =Sheet1!D10-(E10+E40+E55) -> 1418 | F25: =Sheet1!E10-(F10+F40+F55) -> 1503 | G25: =Sheet1!F10-(G10+G40+G55) -> 1154
A26: Income tax expense | B26: Q2 | C26: =Sheet1!B11-(C11+C41+C56) -> 254 | D26: =Sheet1!C11-(D11+D41+D56) -> -88 | E26: =Sheet1!D11-(E11+E41+E56) -> 351 | F26: 241.08 | G26: =Sheet1!F11-(G11+G41+G56) -> 352
A27: NET INCOME (LOSS) | B27: Q2 | C27: =Sheet1!B12-(C12+C42+C57) -> 446 | D27: =Sheet1!C12-(D12+D42+D57) -> -1077 | E27: =Sheet1!D12-(E12+E42+E57) -> 1067 | F27: =F25-F26 -> 1261.92 | G27: =Sheet1!F12-(G12+G42+G57) -> 802
A28: Basic (in dollars per share) | B28: Q2 | C28: 2.55 | D28: 1.63 | E28: 3.64 | F28: 3.83 | G28: 3.27
A29: Diluted (in dollars per share) | B29: Q2 | C29: 2.49 | D29: 1.6 | E29: 3.56 | F29: 3.75 | G29: 3.23
A30: Basic (in shares) | B30: Q2 | C30: 1579.7 | D30: 1558.8 | E30: 1573 | F30: 1578.8 | G30: 1551.6
A31: Diluted (in shares) | B31: Q2 | C31: 1618.4 | D31: 1591.6 | E31: 1609.4 | F31: 1610.8 | G31: 1569.8
A32: Revenues | B32: Q3 | C32: 10660 | D32: 10594 | E32: 12248 | F32: 12687 | G32: 12939
A33: Cost of sales | B33: Q3 | C33: 5789 | D33: 5853 | E33: 6552 | F33: 7072 | G33: 7219
A34: Gross profit | B34: Q3 | C34: 4871 | D34: 4741 | E34: 5696 | F34: 5615 | G34: 5720
A35: Demand creation expense | B35: Q3 | C35: 1018 | D35: 677 | E35: 918 | F35: 943 | G35: 1069
A36: Operating overhead expense | B36: Q3 | C36: 2310 | D36: 2298 | E36: 2654 | F36: 2977 | G36: 3047
A37: Total selling and administrative expense | B37: Q3 | C37: 3328 | D37: 2975 | E37: 3572 | F37: 3920 | G37: 4116
A38: Interest expense (income), net | B38: Q3 | C38: 15 | D38: 65 | E38: 57 | F38: 13 | G38: -34
A39: Other (income) expense, net | B39: Q3 | C39: -33 | D39: -14 | E39: -39 | F39: -146 | G39: -10
... A61: Diluted (in shares) | B61: Q4 | C61: 1594.4 | D61: 1609.5 | E61: 1617.4 | F61: 1572.4 | G61: 1532.1
C64: =C2/C$2 -> 1 | D64: =D2/D$2 -> 1 | E64: =E2/E$2 -> 1 | F64: =F2/F$2 -> 1 | G64: =G2/G$2 -> 1
C65: =C3/C$2 -> 0.54853813 | D65: =D3/D$2 -> 0.55730404 | E65: =E3/E$2 -> 0.54436613 | F65: =F3/F$2 -> 0.53389753 | G65: =G3/G$2 -> 0.56650525
C66: =C4/C$2 -> 0.45146187 | D66: =D4/D$2 -> 0.44269596 | E66: =E4/E$2 -> 0.45563387 | F66: =F4/F$2 -> 0.46610247 | G66: =G4/G$2 -> 0.43349475
...

Sheet Balance Sheet
A1: Particulars | B1: Quarter/Year | C1: 2019 | D1: 2020 | E1: 2021 | F1: 2022 | G1: 2023
A2: Cash and equivalents | B2: Q1 | C2: 3695 | D2: 2863 | E2: 8516 | F2: 8704 | G2: 6955
A3: Short-term investments | B3: Q1 | C3: 351 | D3: 319 | E3: 4012 | F3: 4763 | G3: 3847
A4: Accounts receivable, net | B4: Q1 | C4: 4549 | D4: 4473 | E4: 3669 | F4: 3827 | G4: 4513
A5: Inventories | B5: Q1 | C5: 5415 | D5: 5807 | E5: 6693 | F5: 7700 | G5: 8905
A6: Prepaid expenses and other current assets | B6: Q1 | C6: 1786 | D6: 2282 | E6: 1810 | F6: 1968 | G6: 1815
A7: Total current assets | B7: Q1 | C7: 15796 | D7: 15744 | E7: 24700 | F7: 26962 | G7: 26035
A8: Property, plant and equipment, net | B8: Q1 | C8: 4688 | D8: 4783 | E8: 4958 | F8: 4806 | G8: 4939
A9: Operating lease right-of-use assets, net | B9: Q1 | C9: 0 | D9: 2907 | E9: 3149 | F9: 2959 | G9: 2834
A10: Identifiable intangible assets, net | B10: Q1 | C10: 283 | D10: 275 | E10: 271 | F10: 291 | G10: 277
A11: Goodwill | B11: Q1 | C11: 154 | D11: 223 | E11: 242 | F11: 284 | G11: 281
A12: Deferred income taxes and other assets | B12: Q1 | C12: 2000 | D12: 2288 | E12: 2865 | F12: 3275 | G12: 3928
... A16: Accounts payable | B16: Q1 | C16: 2307 | D16: 2221 | E16: 2257 | F16: 2770 | G16: 2675
A17: Current portion of operating lease liabilities | B17: Q1 | D17: 422 | E17: 470 | F17: 455 | G17: 435
A18: Accrued liabilities | B18: Q1 | C18: 4738 | D18: 5356 | E18: 5907 | F18: 5391 | G18: 5594
A19: Income taxes payable | B19: Q1 | C19: 214 | D19: 268 | E19: 256 | F19: 202 | G19: 330
A20: Total current liabilities | B20: Q1 | C20: 7281 | D20: 8280 | E20: 8894 | F20: 8818 | G20: 9548
A21: Long-term debt | B21: Q1 | C21: 3465 | D21: 3463 | E21: 9412 | F21: 9418 | G21: 8925
A22: Operating lease liabilities | B22: Q1 | C22: 0 | D22: 2758 | E22: 2964 | F22: 2784 | G22: 2692
A23: Deferred income taxes and other liabilities | B23: Q1 | C23: 3214 | D23: 2674 | E23: 2984 | F23: 2748 | G23: 2598
A24: Redeemable preferred stock | B24: Q1 | C24: 0 | D24: 0 | E24: 0 | F24: 0 | G24: 0
A25: Capital in excess of stated value | B25: Q1 | C25: 6910 | D25: 7971 | E25: 9645 | F25: 11186 | G25: 12074
A26: Accumulated other comprehensive income (loss) | B26: Q1 | C26: 197 | D26: -57 | E26: -446 | F26: 99 | G26: 302
A27: Retained earnings | B27: Q1 | C27: 1851 | D27: 1128 | E27: 2729 | F27: 3521 | G27: 2152
A28: Total shareholders’ equity | B28: Q1 | C28: 8961 | D28: 9045 | E28: 11931 | F28: 14809 | G28: 14531
A29: TOTAL LIABILITIES AND SHAREHOLDERS’ EQUITY | B29: Q1 | C29: 22921 | D29: 26220 | E29: 36185 | F29: 38577 | G29: 38294
... A117: Common stock at stated value | B117: Q4 | C117: 3 | D117: 3 | E117: 3 | F117: 3 | G117: 3

Sheet Sheet1
B2: 39117 | C2: 37403 | D2: 44538 | E2: 46710 | F2: 51217
B3: 21643 | C3: 21162 | D3: 24576 | E3: 25231 | F3: 28925
B4: 17474 | C4: 16241 | D4: 19962 | E4: 21479 | F4: 22292
B5: 3753 | C5: 3592 | D5: 3114 | E5: 3850 | F5: 4060
B6: 8949 | C6: 9534 | D6: 9911 | E6: 10954 | F6: 12317
B7: 12702 | C7: 13126 | D7: 13025 | E7: 14804 | F7: 16377
B8: 49 | C8: 89 | D8: 262 | E8: 205 | F8: -6
B9: -78 | C9: 139 | D9: 14 | E9: -181 | F9: -280
B10: 4801 | C10: 2887 | D10: 6661 | E10: 6651 | F10: 6201
B11: 772 | C11: 348 | D11: 934 | E11: 605 | F11: 1131
B12: 4029 | C12: 2539 | D12: 5727 | E12: 6046 | F12: 5070
